Workbook

Sheet Sheet1
D3: Values
A4: CD | B4: nstrata | C4: SPA | D4: Count of Tract | E4: Max of SelectionProb_SPA | F4: Max of SelectionProb_addCD | G4: CD | H4: nstrata | I4: SPA | J4: Key | K4: Sel Prob
A5: 0 | B5: CVCTE | C5: 1 | D5: 20 | E5: 0.55 | F5: 0 | G5: =IF(A5="",G4,A5) -> 0 | H5: =IF(B5="",H4,B5) -> CVCTE | I5: =C5 -> 1 | J5: =CONCATENATE(G5,H5,I5) -> 0CVCTE1 | K5: =F5 -> 0
C6: 2 | D6: 14 | E6: 0.17910448 | F6: 0 | G6: =IF(A6="",G5,A6) -> 0 | H6: =IF(B6="",H5,B6) -> CVCTE | I6: =C6 -> 2 | J6: =CONCATENATE(G6,H6,I6) -> 0CVCTE2 | K6: =F6 -> 0
C7: 3 | D7: 102 | E7: 0.41176471 | F7: 0 | G7: =IF(A7="",G6,A7) -> 0 | H7: =IF(B7="",H6,B7) -> CVCTE | I7: =C7 -> 3 | J7: =CONCATENATE(G7,H7,I7) -> 0CVCTE3 | K7: =F7 -> 0
C8: 5 | D8: 10 | E8: 0.35 | F8: 0 | G8: =IF(A8="",G7,A8) -> 0 | H8: =IF(B8="",H7,B8) -> CVCTE | I8: =C8 -> 5 | J8: =CONCATENATE(G8,H8,I8) -> 0CVCTE5 | K8: =F8 -> 0
C9: 6 | D9: 12 | E9: 0.16393443 | F9: 0 | G9: =IF(A9="",G8,A9) -> 0 | H9: =IF(B9="",H8,B9) -> CVCTE | I9: =C9 -> 6 | J9: =CONCATENATE(G9,H9,I9) -> 0CVCTE6 | K9: =F9 -> 0
C10: 7 | D10: 96 | E10: 0.23958333 | F10: 0 | G10: =IF(A10="",G9,A10) -> 0 | H10: =IF(B10="",H9,B10) -> CVCTE | I10: =C10 -> 7 | J10: =CONCATENATE(G10,H10,I10) -> 0CVCTE7 | K10: =F10 -> 0
C11: 8 | D11: 50 | E11: 0.27272727 | F11: 0 | G11: =IF(A11="",G10,A11) -> 0 | H11: =IF(B11="",H10,B11) -> CVCTE | I11: =C11 -> 8 | J11: =CONCATENATE(G11,H11,I11) -> 0CVCTE8 | K11: =F11 -> 0
B12: FAMILY | C12: 1 | D12: 9 | E12: 1 | F12: 0 | G12: =IF(A12="",G11,A12) -> 0 | H12: =IF(B12="",H11,B12) -> FAMILY | I12: =C12 -> 1 | J12: =CONCATENATE(G12,H12,I12) -> 0FAMILY1 | K12: =F12 -> 0
C13: 3 | D13: 6 | E13: 1 | F13: 0 | G13: =IF(A13="",G12,A13) -> 0 | H13: =IF(B13="",H12,B13) -> FAMILY | I13: =C13 -> 3 | J13: =CONCATENATE(G13,H13,I13) -> 0FAMILY3 | K13: =F13 -> 0
C14: 5 | D14: 2 | E14: 1 | F14: 0 | G14: =IF(A14="",G13,A14) -> 0 | H14: =IF(B14="",H13,B14) -> FAMILY | I14: =C14 -> 5 | J14: =CONCATENATE(G14,H14,I14) -> 0FAMILY5 | K14: =F14 -> 0
C15: 6 | D15: 1 | E15: 1 | F15: 0 | G15: =IF(A15="",G14,A15) -> 0 | H15: =IF(B15="",H14,B15) -> FAMILY | I15: =C15 -> 6 | J15: =CONCATENATE(G15,H15,I15) -> 0FAMILY6 | K15: =F15 -> 0
C16: 7 | D16: 5 | E16: 1 | F16: 0 | G16: =IF(A16="",G15,A16) -> 0 | H16: =IF(B16="",H15,B16) -> FAMILY | I16: =C16 -> 7 | J16: =CONCATENATE(G16,H16,I16) -> 0FAMILY7 | K16: =F16 -> 0
C17: 8 | D17: 4 | E17: 1 | F17: 0 | G17: =IF(A17="",G16,A17) -> 0 | H17: =IF(B17="",H16,B17) -> FAMILY | I17: =C17 -> 8 | J17: =CONCATENATE(G17,H17,I17) -> 0FAMILY8 | K17: =F17 -> 0
B18: INDIV | C18: 1 | D18: 5 | E18: 0.2 | F18: 0 | G18: =IF(A18="",G17,A18) -> 0 | H18: =IF(B18="",H17,B18) -> INDIV | I18: =C18 -> 1 | J18: =CONCATENATE(G18,H18,I18) -> 0INDIV1 | K18: =F18 -> 0
C19: 2 | D19: 17 | E19: 0.048387097 | F19: 0 | G19: =IF(A19="",G18,A19) -> 0 | H19: =IF(B19="",H18,B19) -> INDIV | I19: =C19 -> 2 | J19: =CONCATENATE(G19,H19,I19) -> 0INDIV2 | K19: =F19 -> 0
C20: 3 | D20: 56 | E20: 0.089285714 | F20: 0 | G20: =IF(A20="",G19,A20) -> 0 | H20: =IF(B20="",H19,B20) -> INDIV | I20: =C20 -> 3 | J20: =CONCATENATE(G20,H20,I20) -> 0INDIV3 | K20: =F20 -> 0
C21: 4 | D21: 7 | E21: 0.085106383 | F21: 0 | G21: =IF(A21="",G20,A21) -> 0 | H21: =IF(B21="",H20,B21) -> INDIV | I21: =C21 -> 4 | J21: =CONCATENATE(G21,H21,I21) -> 0INDIV4 | K21: =F21 -> 0
C22: 5 | D22: 7 | E22: 0.076923077 | F22: 0 | G22: =IF(A22="",G21,A22) -> 0 | H22: =IF(B22="",H21,B22) -> INDIV | I22: =C22 -> 5 | J22: =CONCATENATE(G22,H22,I22) -> 0INDIV5 | K22: =F22 -> 0
C23: 6 | D23: 9 | E23: 0.032258065 | F23: 0 | G23: =IF(A23="",G22,A23) -> 0 | H23: =IF(B23="",H22,B23) -> INDIV | I23: =C23 -> 6 | J23: =CONCATENATE(G23,H23,I23) -> 0INDIV6 | K23: =F23 -> 0
C24: 7 | D24: 55 | E24: 0.090909091 | F24: 0 | G24: =IF(A24="",G23,A24) -> 0 | H24: =IF(B24="",H23,B24) -> INDIV | I24: =C24 -> 7 | J24: =CONCATENATE(G24,H24,I24) -> 0INDIV7 | K24: =F24 -> 0
C25: 8 | D25: 39 | E25: 0.068181818 | F25: 0 | G25: =IF(A25="",G24,A25) -> 0 | H25: =IF(B25="",H24,B25) -> INDIV | I25: =C25 -> 8 | J25: =CONCATENATE(G25,H25,I25) -> 0INDIV8 | K25: =F25 -> 0
B26: NON-HS | C26: 1 | D26: 50 | E26: 0.02 | F26: 0 | G26: =IF(A26="",G25,A26) -> 0 | H26: =IF(B26="",H25,B26) -> NON-HS | I26: =C26 -> 1 | J26: =CONCATENATE(G26,H26,I26) -> 0NON-HS1 | K26: =F26 -> 0
C27: 2 | D27: 83 | E27: 0.022140221 | F27: 0 | G27: =IF(A27="",G26,A27) -> 0 | H27: =IF(B27="",H26,B27) -> NON-HS | I27: =C27 -> 2 | J27: =CONCATENATE(G27,H27,I27) -> 0NON-HS2 | K27: =F27 -> 0
C28: 3 | D28: 194 | E28: 0.030927835 | F28: 0 | G28: =IF(A28="",G27,A28) -> 0 | H28: =IF(B28="",H27,B28) -> NON-HS | I28: =C28 -> 3 | J28: =CONCATENATE(G28,H28,I28) -> 0NON-HS3 | K28: =F28 -> 0
C29: 4 | D29: 1 | E29: 0.026315789 | F29: 0 | G29: =IF(A29="",G28,A29) -> 0 | H29: =IF(B29="",H28,B29) -> NON-HS | I29: =C29 -> 4 | J29: =CONCATENATE(G29,H29,I29) -> 0NON-HS4 | K29: =F29 -> 0
C30: 5 | D30: 23 | E30: 0.032258065 | F30: 0 | G30: =IF(A30="",G29,A30) -> 0 | H30: =IF(B30="",H29,B30) -> NON-HS | I30: =C30 -> 5 | J30: =CONCATENATE(G30,H30,I30) -> 0NON-HS5 | K30: =F30 -> 0
C31: 6 | D31: 48 | E31: 0.0234375 | F31: 0 | G31: =IF(A31="",G30,A31) -> 0 | H31: =IF(B31="",H30,B31) -> NON-HS | I31: =C31 -> 6 | J31: =CONCATENATE(G31,H31,I31) -> 0NON-HS6 | K31: =F31 -> 0
C32: 7 | D32: 132 | E32: 0.045454545 | F32: 0 | G32: =IF(A32="",G31,A32) -> 0 | H32: =IF(B32="",H31,B32) -> NON-HS | I32: =C32 -> 7 | J32: =CONCATENATE(G32,H32,I32) -> 0NON-HS7 | K32: =F32 -> 0
C33: 8 | D33: 99 | E33: 0.033333333 | F33: 0 | G33: =IF(A33="",G32,A33) -> 0 | H33: =IF(B33="",H32,B33) -> NON-HS | I33: =C33 -> 8 | J33: =CONCATENATE(G33,H33,I33) -> 0NON-HS8 | K33: =F33 -> 0
A34: 1 | B34: CVCTE | C34: 4 | D34: 25 | E34: 0.16438356 | F34: 0.30434783 | G34: =IF(A34="",G33,A34) -> 1 | H34: =IF(B34="",H33,B34) -> CVCTE | I34: =C34 -> 4 | J34: =CONCATENATE(G34,H34,I34) -> 1CVCTE4 | K34: =F34 -> 0.30434783
B35: FAMILY | C35: 4 | D35: 3 | E35: 1 | F35: 0 | G35: =IF(A35="",G34,A35) -> 1 | H35: =IF(B35="",H34,B35) -> FAMILY | I35: =C35 -> 4 | J35: =CONCATENATE(G35,H35,I35) -> 1FAMILY4 | K35: =F35 -> 0
B36: INDIV | C36: 4 | D36: 9 | E36: 0.085106383 | F36: 0 | G36: =IF(A36="",G35,A36) -> 1 | H36: =IF(B36="",H35,B36) -> INDIV | I36: =C36 -> 4 | J36: =CONCATENATE(G36,H36,I36) -> 1INDIV4 | K36: =F36 -> 0
C37: 6 | D37: 1 | E37: 0.032258065 | F37: 0 | G37: =IF(A37="",G36,A37) -> 1 | H37: =IF(B37="",H36,B37) -> INDIV | I37: =C37 -> 6 | J37: =CONCATENATE(G37,H37,I37) -> 1INDIV6 | K37: =F37 -> 0
B38: NON-HS | C38: 4 | D38: 30 | E38: 0.026315789 | F38: 0.1 | G38: =IF(A38="",G37,A38) -> 1 | H38: =IF(B38="",H37,B38) -> NON-HS | I38: =C38 -> 4 | J38: =CONCATENATE(G38,H38,I38) -> 1NON-HS4 | K38: =F38 -> 0.1
C39: 6 | D39: 2 | E39: 0.0234375 | F39: 0 | G39: =IF(A39="",G38,A39) -> 1 | H39: =IF(B39="",H38,B39) -> NON-HS | I39: =C39 -> 6 | J39: =CONCATENATE(G39,H39,I39) -> 1NON-HS6 | K39: =F39 -> 0
A40: 2 | B40: CVCTE | C40: 2 | D40: 28 | E40: 0.17910448 | F40: 0.36363636 | G40: =IF(A40="",G39,A40) -> 2 | H40: =IF(B40="",H39,B40) -> CVCTE | I40: =C40 -> 2 | J40: =CONCATENATE(G40,H40,I40) -> 2CVCTE2 | K40: =F40 -> 0.36363636
B41: FAMILY | C41: 2 | D41: 1 | E41: 1 | F41: 0 | G41: =IF(A41="",G40,A41) -> 2 | H41: =IF(B41="",H40,B41) -> FAMILY | I41: =C41 -> 2 | J41: =CONCATENATE(G41,H41,I41) -> 2FAMILY2 | K41: =F41 -> 0
B42: INDIV | C42: 2 | D42: 11 | E42: 0.048387097 | F42: 0.18181818 | G42: =IF(A42="",G41,A42) -> 2 | H42: =IF(B42="",H41,B42) -> INDIV | I42: =C42 -> 2 | J42: =CONCATENATE(G42,H42,I42) -> 2INDIV2 | K42: =F42 -> 0.18181818
...

Sheet Sheet2
A3: Row Labels | B3: Count of Tract | C3: Sum of SamplingWeight_CD
A4: 0 | B4: 1156 | C4: 1225.6048
A5: CVCTE | B5: 304 | C5: 319.9381
A6: FAMILY | B6: 27 | C6: 27
A7: INDIV | B7: 195 | C7: 180.66667
A8: NON-HS | B8: 630 | C8: 698
A9: 1 | B9: 70 | C9: 67.890336
A10: CVCTE | B10: 25 | C10: 28.885017
A11: FAMILY | B11: 3 | C11: 3
A12: INDIV | B12: 10 | C12: 11.75
A13: NON-HS | B13: 32 | C13: 24.255319
A14: 2 | B14: 68 | C14: 126.59718
A15: CVCTE | B15: 28 | C15: 50.25
A16: FAMILY | B16: 1 | C16: 1
A17: INDIV | B17: 11 | C17: 9.0331126
A18: NON-HS | B18: 28 | C18: 66.314066
A19: 3 | B19: 60 | C19: 80.447221
A20: CVCTE | B20: 18 | C20: 21.695412
A21: FAMILY | B21: 1 | C21: 1
A22: INDIV | B22: 6 | C22: 24.855856
A23: NON-HS | B23: 35 | C23: 32.895954
A24: 4 | B24: 69 | C24: 72.942062
A25: CVCTE | B25: 8 | C25: 14.835714
A26: FAMILY | B26: 1 | C26: 1
A27: INDIV | B27: 16 | C27: 22.6
A28: NON-HS | B28: 44 | C28: 34.506348
A29: 5 | B29: 69 | C29: 79.47519
A30: CVCTE | B30: 9 | C30: 16.003361
A31: INDIV | B31: 9 | C31: 29.083333
A32: NON-HS | B32: 51 | C32: 34.388495
A33: 6 | B33: 66 | C33: 159.587
A34: CVCTE | B34: 29 | C34: 45.586996
A35: FAMILY | B35: 3 | C35: 3
A36: INDIV | B36: 8 | C36: 20.666667
A37: NON-HS | B37: 26 | C37: 90.333333
A38: 7 | B38: 65 | C38: 122.16678
A39: CVCTE | B39: 28 | C39: 50.978261
A40: FAMILY | B40: 2 | C40: 2
A41: INDIV | B41: 9 | C41: 7.6965517
A42: NON-HS | B42: 26 | C42: 61.491968
...

Sheet Data
A1: =[1]Data!A1 -> Tract | B1: =[1]Data!B1 -> SPA | C1: =[1]Data!C1 -> CD | D1: =[1]Data!D1 -> SD | E1: =[1]Data!E1 -> nstrata | F1: =[1]Data!F1 -> Community_Name | G1: =[1]Data!G1 -> selected_spa | H1: =[1]Data!H1 -> selected_cd | ... S1: =[1]Data!S1 -> SamplingWeight_addCD | T1: Selection Prob_CD | U1: SamplingWeight_CD | Y1: Selection Prob_CD
A2: =[1]Data!A2 -> 900806 | B2: =[1]Data!B2 -> 1 | C2: =[1]Data!C2 -> 0 | D2: =[1]Data!D2 -> 5 | E2: =[1]Data!E2 -> CVCTE | F2: =[1]Data!F2 -> Lancaster | G2: =[1]Data!G2 -> 1 | H2: =[1]Data!H2 -> 1 | ... S2: =[1]Data!S2 -> 0 | T2: =N2+Y2*(1-N2) -> 0.55 | U2: =IF(T2="",0,1/T2*H2) -> 1.8181818 | V2: =TEXT(C2,"0") -> 0 | W2: =TEXT(B2,"0") -> 1 | X2: =CONCATENATE(V2,E2,W2) -> 0CVCTE1 | Y2: =VLOOKUP(X2,Sheet1!$J$5:$K$121,2,FALSE) -> 0
A3: =[1]Data!A3 -> 900300 | B3: =[1]Data!B3 -> 1 | C3: =[1]Data!C3 -> 0 | D3: =[1]Data!D3 -> 5 | E3: =[1]Data!E3 -> CVCTE | F3: =[1]Data!F3 -> Unincorporated Antelope Valley | G3: =[1]Data!G3 -> 1 | H3: =[1]Data!H3 -> 1 | ... S3: =[1]Data!S3 -> 0 | T3: =N3+Y3*(1-N3) -> 0.55 | U3: =IF(T3="",0,1/T3*H3) -> 1.8181818 | V3: =TEXT(C3,"0") -> 0 | W3: =TEXT(B3,"0") -> 1 | X3: =CONCATENATE(V3,E3,W3) -> 0CVCTE1 | Y3: =VLOOKUP(X3,Sheet1!$J$5:$K$121,2,FALSE) -> 0
A4: =[1]Data!A4 -> 900103 | B4: =[1]Data!B4 -> 1 | C4: =[1]Data!C4 -> 0 | D4: =[1]Data!D4 -> 5 | E4: =[1]Data!E4 -> CVCTE | F4: =[1]Data!F4 -> Unincorporated Antelope Valley | G4: =[1]Data!G4 -> 1 | H4: =[1]Data!H4 -> 1 | ... S4: =[1]Data!S4 -> 0 | T4: =N4+Y4*(1-N4) -> 0.55 | U4: =IF(T4="",0,1/T4*H4) -> 1.8181818 | V4: =TEXT(C4,"0") -> 0 | W4: =TEXT(B4,"0") -> 1 | X4: =CONCATENATE(V4,E4,W4) -> 0CVCTE1 | Y4: =VLOOKUP(X4,Sheet1!$J$5:$K$121,2,FALSE) -> 0
A5: =[1]Data!A5 -> 910401 | B5: =[1]Data!B5 -> 1 | C5: =[1]Data!C5 -> 0 | D5: =[1]Data!D5 -> 5 | E5: =[1]Data!E5 -> CVCTE | F5: =[1]Data!F5 -> Palmdale | G5: =[1]Data!G5 -> 0 | H5: =[1]Data!H5 -> 0 | ... S5: =[1]Data!S5 -> 0 | T5: =N5+Y5*(1-N5) -> 0.55 | U5: =IF(T5="",0,1/T5*H5) -> 0 | V5: =TEXT(C5,"0") -> 0 | W5: =TEXT(B5,"0") -> 1 | X5: =CONCATENATE(V5,E5,W5) -> 0CVCTE1 | Y5: =VLOOKUP(X5,Sheet1!$J$5:$K$121,2,FALSE) -> 0
A6: =[1]Data!A6 -> 900900 | B6: =[1]Data!B6 -> 1 | C6: =[1]Data!C6 -> 0 | D6: =[1]Data!D6 -> 5 | E6: =[1]Data!E6 -> CVCTE | F6: =[1]Data!F6 -> Unincorporated Antelope Valley | G6: =[1]Data!G6 -> 1 | H6: =[1]Data!H6 -> 1 | ... S6: =[1]Data!S6 -> 0 | T6: =N6+Y6*(1-N6) -> 0.55 | U6: =IF(T6="",0,1/T6*H6) -> 1.8181818 | V6: =TEXT(C6,"0") -> 0 | W6: =TEXT(B6,"0") -> 1 | X6: =CONCATENATE(V6,E6,W6) -> 0CVCTE1 | Y6: =VLOOKUP(X6,Sheet1!$J$5:$K$121,2,FALSE) -> 0
A7: =[1]Data!A7 -> 900609 | B7: =[1]Data!B7 -> 1 | C7: =[1]Data!C7 -> 0 | D7: =[1]Data!D7 -> 5 | E7: =[1]Data!E7 -> CVCTE | F7: =[1]Data!F7 -> Lancaster | G7: =[1]Data!G7 -> 1 | H7: =[1]Data!H7 -> 1 | ... S7: =[1]Data!S7 -> 0 | T7: =N7+Y7*(1-N7) -> 0.55 | U7: =IF(T7="",0,1/T7*H7) -> 1.8181818 | V7: =TEXT(C7,"0") -> 0 | W7: =TEXT(B7,"0") -> 1 | X7: =CONCATENATE(V7,E7,W7) -> 0CVCTE1 | Y7: =VLOOKUP(X7,Sheet1!$J$5:$K$121,2,FALSE) -> 0
A8: =[1]Data!A8 -> 901209 | B8: =[1]Data!B8 -> 1 | C8: =[1]Data!C8 -> 0 | D8: =[1]Data!D8 -> 5 | E8: =[1]Data!E8 -> CVCTE | F8: =[1]Data!F8 -> Unincorporated Antelope Valley | G8: =[1]Data!G8 -> 0 | H8: =[1]Data!H8 -> 0 | ... S8: =[1]Data!S8 -> 0 | T8: =N8+Y8*(1-N8) -> 0.55 | U8: =IF(T8="",0,1/T8*H8) -> 0 | V8: =TEXT(C8,"0") -> 0 | W8: =TEXT(B8,"0") -> 1 | X8: =CONCATENATE(V8,E8,W8) -> 0CVCTE1 | Y8: =VLOOKUP(X8,Sheet1!$J$5:$K$121,2,FALSE) -> 0
A9: =[1]Data!A9 -> 900607 | B9: =[1]Data!B9 -> 1 | C9: =[1]Data!C9 -> 0 | D9: =[1]Data!D9 -> 5 | E9: =[1]Data!E9 -> CVCTE | F9: =[1]Data!F9 -> Lancaster | G9: =[1]Data!G9 -> 0 | H9: =[1]Data!H9 -> 0 | ... S9: =[1]Data!S9 -> 0 | T9: =N9+Y9*(1-N9) -> 0.55 | U9: =IF(T9="",0,1/T9*H9) -> 0 | V9: =TEXT(C9,"0") -> 0 | W9: =TEXT(B9,"0") -> 1 | X9: =CONCATENATE(V9,E9,W9) -> 0CVCTE1 | Y9: =VLOOKUP(X9,Sheet1!$J$5:$K$121,2,FALSE) -> 0
A10: =[1]Data!A10 -> 910403 | B10: =[1]Data!B10 -> 1 | C10: =[1]Data!C10 -> 0 | D10: =[1]Data!D10 -> 5 | E10: =[1]Data!E10 -> CVCTE | F10: =[1]Data!F10 -> Palmdale | G10: =[1]Data!G10 -> 1 | H10: =[1]Data!H10 -> 1 | ... S10: =[1]Data!S10 -> 0 | T10: =N10+Y10*(1-N10) -> 0.55 | U10: =IF(T10="",0,1/T10*H10) -> 1.8181818 | V10: =TEXT(C10,"0") -> 0 | W10: =TEXT(B10,"0") -> 1 | X10: =CONCATENATE(V10,E10,W10) -> 0CVCTE1 | Y10: =VLOOKUP(X10,Sheet1!$J$5:$K$121,2,FALSE) -> 0
A11: =[1]Data!A11 -> 900602 | B11: =[1]Data!B11 -> 1 | C11: =[1]Data!C11 -> 0 | D11: =[1]Data!D11 -> 5 | E11: =[1]Data!E11 -> CVCTE | F11: =[1]Data!F11 -> Lancaster | G11: =[1]Data!G11 -> 1 | H11: =[1]Data!H11 -> 1 | ... S11: =[1]Data!S11 -> 0 | T11: =N11+Y11*(1-N11) -> 0.55 | U11: =IF(T11="",0,1/T11*H11) -> 1.8181818 | V11: =TEXT(C11,"0") -> 0 | W11: =TEXT(B11,"0") -> 1 | X11: =CONCATENATE(V11,E11,W11) -> 0CVCTE1 | Y11: =VLOOKUP(X11,Sheet1!$J$5:$K$121,2,FALSE) -> 0
A12: =[1]Data!A12 -> 910501 | B12: =[1]Data!B12 -> 1 | C12: =[1]Data!C12 -> 0 | D12: =[1]Data!D12 -> 5 | E12: =[1]Data!E12 -> CVCTE | F12: =[1]Data!F12 -> Palmdale | G12: =[1]Data!G12 -> 1 | H12: =[1]Data!H12 -> 1 | ... S12: =[1]Data!S12 -> 0 | T12: =N12+Y12*(1-N12) -> 0.55 | U12: =IF(T12="",0,1/T12*H12) -> 1.8181818 | V12: =TEXT(C12,"0") -> 0 | W12: =TEXT(B12,"0") -> 1 | X12: =CONCATENATE(V12,E12,W12) -> 0CVCTE1 | Y12: =VLOOKUP(X12,Sheet1!$J$5:$K$121,2,FALSE) -> 0
A13: =[1]Data!A13 -> 901008 | B13: =[1]Data!B13 -> 1 | C13: =[1]Data!C13 -> 0 | D13: =[1]Data!D13 -> 5 | E13: =[1]Data!E13 -> CVCTE | F13: =[1]Data!F13 -> Lancaster | G13: =[1]Data!G13 -> 1 | H13: =[1]Data!H13 -> 1 | ... S13: =[1]Data!S13 -> 0 | T13: =N13+Y13*(1-N13) -> 0.55 | U13: =IF(T13="",0,1/T13*H13) -> 1.8181818 | V13: =TEXT(C13,"0") -> 0 | W13: =TEXT(B13,"0") -> 1 | X13: =CONCATENATE(V13,E13,W13) -> 0CVCTE1 | Y13: =VLOOKUP(X13,Sheet1!$J$5:$K$121,2,FALSE) -> 0
... A2161: =[1]Data!A2161 -> 980031 | B2161: =[1]Data!B2161 -> 8 | C2161: =[1]Data!C2161 -> 15 | D2161: =[1]Data!D2161 -> 4 | E2161: =[1]Data!E2161 -> NON-HS | F2161: =[1]Data!F2161 -> Wilmington | G2161: =[1]Data!G2161 -> 0 | H2161: =[1]Data!H2161 -> 0 | ... S2161: =[1]Data!S2161 -> 0 | T2161: =N2161+Y2161*(1-N2161) -> 0.079365079 | U2161: =IF(T2161="",0,1/T2161*H2161) -> 0 | V2161: =TEXT(C2161,"0") -> 15 | W2161: =TEXT(B2161,"0") -> 8 | X2161: =CONCATENATE(V2161,E2161,W2161) -> 15NON-HS8 | Y2161: =VLOOKUP(X2161,Sheet1!$J$5:$K$121,2,FALSE) -> 0.047619048
G2163: =SUM(G2:G2161) -> 293 | H2163: =SUM(H2:H2161) -> 449 | I2163: =SUM(I2:I2161) -> 36648.337 | J2163: =SUM(J2:J2161) -> 25968.105 | K2163: =SUM(K2:K2161) -> 35555.105 | L2163: =SUM(L2:L2161) -> 1209.9227 | M2163: =SUM(M2:M2161) -> 36765.028 | N2163: =SUM(N2:N2161) -> 293 | O2163: =SUM(O2:O2161) -> 2160 | R2163: =SUM(R2:R2161) -> 156 | U2163: =SUM(U2:U2161) -> 2375.2093
R2164: =R2163+N2163 -> 449
